Workbook

Sheet Product list
A1: Standardize | B1: Product Code | C1: Income Account | D1: Expense Account | E1: Product Category | F1: Product Type | G1: Product Name TH | H1: Product Name EN | I1: UOM TH | J1: UOM EN | K1: Code Supplier | L1: Supplier Name | M1: Sellable/Not Sellable | N1: Selling Price | O1: Cost Price
A2: Standard | B2: AX-3M233-TH | C2: 513025 | D2: 513025 | E2: Tape | F2: Storable Product | G2: เทปกาว 3M | H2: Masking tape | I2: ชิ้น | J2: PC | K2: AP-CST000 | L2: =IFERROR(VLOOKUP(K2,'Supplier list'!B:C,2,0),"") | M2: Not Sellable | O2: 202
A3: Standard | B3: AX-513004-TH | C3: 513025 | D3: 513025 | E3: buy-sell | F3: Storable Product | G3: ซื้อมา-ขายไป | H3: Buy-Sell | I3: ชิ้น | J3: PC | K3: - | L3: =IFERROR(VLOOKUP(K3,'Supplier list'!B:C,2,0),"") | M3: Not Sellable | O3: 0
A4: Standard | B4: AX-513006-TH | C4: 513025 | D4: 513025 | E4: Service | F4: Storable Product | G4: ค่าใช้จ่าย-นำเข้า | H4: Import Fee | I4: งาน | J4: JOB | K4: - | L4: =IFERROR(VLOOKUP(K4,'Supplier list'!B:C,2,0),"") | M4: Not Sellable | O4: 0
A5: Standard | B5: AX-513007-TH | C5: 513025 | D5: 513025 | E5: Service | F5: Storable Product | G5: ค่าใช้จ่าย-ส่งออก | H5: Export Fee | I5: งาน | J5: JOB | K5: - | L5: =IFERROR(VLOOKUP(K5,'Supplier list'!B:C,2,0),"") | M5: Not Sellable | O5: 0
A6: Standard | B6: AX-531016-TH | C6: 513025 | D6: 513025 | E6: Service | F6: Storable Product | G6: ค่าสวัสดิการอื่นๆ-เลี้ยงข้าวพนักงาน | H6: Other welfare expenses - food for employees | I6: งาน | J6: JOB | K6: - | L6: =IFERROR(VLOOKUP(K6,'Supplier list'!B:C,2,0),"") | M6: Not Sellable | O6: 0
A7: Standard | B7: AX-CGM00-TH | C7: 513025 | D7: 513025 | E7: Tape | F7: Storable Product | G7: เทปกาว | H7: Masking tape | I7: ชิ้น | J7: PC | K7: AP-BNT000 | L7: =IFERROR(VLOOKUP(K7,'Supplier list'!B:C,2,0),"") | M7: Not Sellable | O7: 84
A8: Standard | B8: AX-PH007-TH | C8: 513025 | D8: 513025 | E8: Carpet | F8: Storable Product | G8: พื้นพรมแผ่นรุ่น PH07 | H8: Carpet floor sheet model PH07 | I8: ตรม. | J8: SQM | K8: AP-SFL000 | L8: =IFERROR(VLOOKUP(K8,'Supplier list'!B:C,2,0),"") | M8: Not Sellable | O8: 680
A9: Standard | B9: AX-PT00-001 | C9: 513025 | D9: 513025 | E9: Cardboard cylinder | F9: Storable Product | G9: Paper Tube/กระบอกภาชนะกระดาษแข็ง | H9: Cardboard cylinder with spray paint | I9: ชิ้น | J9: PC | K9: AP-QNL000 | L9: =IFERROR(VLOOKUP(K9,'Supplier list'!B:C,2,0),"") -> CO.,LTD QINGDAO NEW LIBERTY INT'L TRADING CO.LTD. | M9: Not Sellable | O9: 0.35
A10: Standard | B10: AX-PT00-002 | C10: 513025 | D10: 513025 | E10: Service | F10: Storable Product | G10: ค่าส่งสินค้าอื่นๆ | H10: Other shipping costs | I10: งาน | J10: JOB | K10: - | L10: =IFERROR(VLOOKUP(K10,'Supplier list'!B:C,2,0),"") | M10: Not Sellable | O10: 0
A11: Standard | B11: FC-0001 | C11: 513025 | D11: 513025 | E11: Honeycomb | F11: Storable Product | G11: กระดาษรังผึ้ง honeycomb กว้าง60xยาว30 หนา10 cm. | H11: Honey Comb 60x30x10 cm. | I11: ชิ้น | J11: PC | K11: AP-QNL000 | L11: =IFERROR(VLOOKUP(K11,'Supplier list'!B:C,2,0),"") -> CO.,LTD QINGDAO NEW LIBERTY INT'L TRADING CO.LTD. | M11: Not Sellable | O11: 5.7
A12: Standard | B12: FC-0002 | C12: 513025 | D12: 513025 | E12: Tool | F12: Storable Product | G12: เครื่องเจียร์ไฟฟ้า 4" MAKITA 9500NB | H12: Electric Grinder 4MAKITA9500NB" | I12: ชิ้น | J12: PC | K12: AP-GDL000 | L12: =IFERROR(VLOOKUP(K12,'Supplier list'!B:C,2,0),"") -> หจก. กรีน ดิสทริบิวชั่น | M12: Not Sellable | O12: 2990
A13: Standard | B13: FC-0003 | C13: 513025 | D13: 513025 | E13: Tool | F13: Storable Product | G13: ถังกาพ่น M-871 | H13: Spray Gun M-871 | I13: ชิ้น | J13: PC | K13: - | L13: =IFERROR(VLOOKUP(K13,'Supplier list'!B:C,2,0),"") | M13: Not Sellable | O13: 4200
... A23: Standard | B23: FC-0013 | C23: 513025 | D23: 513025 | E23: Light bulb | F23: Storable Product | G23: หลอดไฟ (ยาว) | H23: Light bulb (long) | I23: หลอด | J23: TUBE | K23: AP-TPK001 | L23: =IFERROR(VLOOKUP(K23,'Supplier list'!B:C,2,0),"") -> บริษัท ที.พี.เค ไทยเมท แมชชีนทูลล์ จำกัด | M23: Not Sellable | O23: 229
A24: Standard | B24: FC-0014 | C24: 513025 | D24: 513025 | E24: Light bulb | F24: Storable Product | G24: หลอดไฟ (สั้น) | H24: Light bulb (short) | I24: หลอด | J24: TUBE | L24: =IFERROR(VLOOKUP(K24,'Supplier list'!B:C,2,0),"") | M24: Not Sellable | O24: 63
A25: Standard | B25: FC-0015 | C25: 513025 | D25: 513025 | E25: Tool | F25: Storable Product | G25: หัวปืน M-871 (จีน) | H25: Gun head M-871 (China) | I25: ชิ้น | J25: PC | K25: - | L25: =IFERROR(VLOOKUP(K25,'Supplier list'!B:C,2,0),"") | M25: Not Sellable | O25: 0
A26: Standard | B26: FC-0016 | C26: 513025 | D26: 513025 | E26: Tool | F26: Storable Product | G26: หัวจี้ลม แกน 3 mm. | H26: Air pendant 3 mm. | I26: ชิ้น | J26: PC | K26: - | L26: =IFERROR(VLOOKUP(K26,'Supplier list'!B:C,2,0),"") | M26: Not Sellable | O26: 0
A27: Standard | B27: FC-0017 | C27: 513025 | D27: 513025 | E27: Screw | F27: Storable Product | G27: สกรูมิลดำ 12x55+หัว+อีแปะ | H27: Hexagon Screw Black 12x55 | I27: ชุด | J27: SET | K27: AP-KSR001 | L27: =IFERROR(VLOOKUP(K27,'Supplier list'!B:C,2,0),"") -> บริษัท เกรียงศิริพัฒนา (1995) จำกัด | M27: Not Sellable | O27: 15
A28: Standard | B28: FC-0020 | C28: 513025 | D28: 513025 | E28: Joint | F28: Storable Product | G28: คอปเปอร์ 3 ทาง T | H28: Coupler 3 Way Multi Pass ,T | I28: ชิ้น | J28: PC | K28: AP-KSR001 | L28: =IFERROR(VLOOKUP(K28,'Supplier list'!B:C,2,0),"") -> บริษัท เกรียงศิริพัฒนา (1995) จำกัด | M28: Not Sellable | O28: 190
A29: Standard | B29: FC-0021 | C29: 513025 | D29: 513025 | E29: Joint | F29: Storable Product | G29: ข้อต่อคอปเปอร์ 20pm. | H29: Coupler joint, model 20PM | I29: ชิ้น | J29: PC | K29: AP-KSR001 | L29: =IFERROR(VLOOKUP(K29,'Supplier list'!B:C,2,0),"") -> บริษัท เกรียงศิริพัฒนา (1995) จำกัด | M29: Not Sellable | O29: 20
A30: Standard | B30: FC-0023 | C30: 513025 | D30: 513025 | E30: Drill bits | F30: Storable Product | G30: ดอกเจาะกระจก 8มม. | H30: Glass drill bit 8 mm. | I30: ชิ้น | J30: PC | K30: AP-KSR001 | L30: =IFERROR(VLOOKUP(K30,'Supplier list'!B:C,2,0),"") -> บริษัท เกรียงศิริพัฒนา (1995) จำกัด | M30: Not Sellable | O30: 200
A31: Standard | B31: FC-0024 | C31: 513025 | D31: 513025 | E31: Battery | F31: Storable Product | G31: 005.23.601 BRUSH ET-BG 240V CT26/36 | H31: 005.23.601 BRUSH ET-BG 240V CT26/36 | I31: ชิ้น | J31: PC | K31: AP-HAF001 | L31: =IFERROR(VLOOKUP(K31,'Supplier list'!B:C,2,0),"") -> บริษัท เฮเฟเล่ (ประเทศไทย) จำกัด | M31: Not Sellable | O31: 1776
A32: Standard | B32: FC-0026 | C32: 513025 | D32: 513025 | E32: Wheel | F32: Storable Product | G32: ล้อไนลอนขาวชุดชุบโครเมียม แป้นเป็น 4" | H32: Wheels, white nylon, chrome plated set, backplate 4" | I32: กล่อง | J32: BOX | K32: AP-KCR000 | L32: =IFERROR(VLOOKUP(K32,'Supplier list'!B:C,2,0),"") | M32: Not Sellable | O32: 435
A33: Standard | B33: FC-0027 | C33: 513025 | D33: 513025 | E33: Bathroom cleaner | F33: Storable Product | G33: น้ำยาล้างห้องน้ำ (เป็ดโปร) | H33: Bathroom cleaner (Duck Pro) | I33: ขวด | J33: BOTTLES | K33: AP-SMK000 | L33: =IFERROR(VLOOKUP(K33,'Supplier list'!B:C,2,0),"") -> บริษัท สยามแม็คโคร จำกัด (มหาชน) | M33: Not Sellable | O33: 209
A34: Standard | B34: FC-0028 | C34: 513025 | D34: 513025 | E34: Screw | F34: Storable Product | G34: สกรูมิล JF M4x8-0.70 | H34: Hexagon Screw JF M4x8-0.70 | I34: ชิ้น | J34: PC | K34: AP-KCR000 | L34: =IFERROR(VLOOKUP(K34,'Supplier list'!B:C,2,0),"") -> บริษัท ก.เจริญฮาร์ดแวร์ จำกัด | M34: Not Sellable | O34: 0.25
A35: Standard | B35: FC-0029 | C35: 513025 | D35: 513025 | E35: Drill bits | F35: Storable Product | G35: โฮลซอเจาะไม้ 7 ใบ/ชุด 26-63มม. | H35: Hole Saw 7 wood drill bits/set 26-63mm. | I35: ชุด | J35: SET | K35: AP-SHM000 | L35: =IFERROR(VLOOKUP(K35,'Supplier list'!B:C,2,0),"") -> บริษัท ซูเปอร์โฮมมาร์ท จำกัด (สำนักงานใหญ่) | M35: Not Sellable | O35: 115
A36: Standard | B36: FC-0030 | C36: 513025 | D36: 513025 | E36: EPE Foam | F36: Storable Product | G36: EPE Foam Laminate inside (handle J) | H36: EPE Foam Laminate inside (handle J) | I36: ชิ้น | J36: PC | K36: AP-PCP000 | L36: =IFERROR(VLOOKUP(K36,'Supplier list'!B:C,2,0),"") | M36: Not Sellable | O36: 4.5
... A63: Standard | B63: FS-FUFIT-002 | C63: 114003 | D63: 114003 | E63: Rubber Bump Button | F63: Storable Product | G63: 483.01.996 ปุ่มยางกันกระแทก | H63: 483.01.996 Rubber Bump Button | I63: แผง | J63: PANEL | K63: AP-HAF001 | L63: =IFERROR(VLOOKUP(K63,'Supplier list'!B:C,2,0),"") -> บริษัท เฮเฟเล่ (ประเทศไทย) จำกัด | M63: Not Sellable | O63: 178
A64: Standard | B64: FS-FUFIT-003 | C64: 114003 | D64: 114003 | E64: Triangle Claw Bumper | F64: Storable Product | G64: กันชนก้ามปูสามเหลี่ยม BARCO | H64: BARCO Triangle Claw Bumper | I64: ชิ้น | J64: PC | L64: =IFERROR(VLOOKUP(K64,'Supplier list'!B:C,2,0),"") | M64: Not Sellable | O64: 28
A65: Standard | B65: FS-FUFIT-004 | C65: 114003 | D65: 114003 | E65: Push Catches | F65: Storable Product | G65: กดเปิดหน้าบานแบบแม่เหล็ก XL | H65: Press to open the magnetic door XL | I65: ชิ้น | J65: PC | L65: =IFERROR(VLOOKUP(K65,'Supplier list'!B:C,2,0),"") | M65: Not Sellable | O65: 68
A66: Standard | B66: FS-FUFIT-008 | C66: 114003 | D66: 114003 | E66: Staples | F66: Storable Product | G66: ลูกแม็กขาคู่รุ่น1010J ขนาด 10x10 | H66: Double leg alloy, model 1010J, size 10x10 | I66: กล่อง | J66: BOX | K66: AP-KSR001 | L66: =IFERROR(VLOOKUP(K66,'Supplier list'!B:C,2,0),"") | M66: Not Sellable | O66: 100
A67: Standard | B67: FS-FUFIT-009 | C67: 114003 | D67: 114003 | E67: Nails | F67: Storable Product | G67: ตะปูยิงงานฝีมือ HI-TOP # PINS/25 | H67: HI-TOP Craft Nails # PINS/25 | I67: กล่อง | J67: BOX | L67: =IFERROR(VLOOKUP(K67,'Supplier list'!B:C,2,0),"") | M67: Not Sellable | O67: 261
A68: Standard | B68: FS-FUFIT-010 | C68: 114003 | D68: 114003 | E68: Power cord with jack | F68: Storable Product | G68: สายไฟพร้อมแจ๊คเสียบ | H68: Power cord with jack | I68: เส้น | J68: STRIP | L68: =IFERROR(VLOOKUP(K68,'Supplier list'!B:C,2,0),"") | M68: Not Sellable | O68: 60
A69: Standard | B69: FS-FUFIT-011 | C69: 114003 | D69: 114003 | E69: Staples | F69: Storable Product | G69: ลูกแม็กขาคู่รุ่น416J ขนาด 4x16 | H69: Staples Double pin model 416J, size 4x16 | I69: กล่อง | J69: BOX | L69: =IFERROR(VLOOKUP(K69,'Supplier list'!B:C,2,0),"") | M69: Not Sellable | O69: 93
A70: Standard | B70: FS-FUFIT-012 | C70: 114003 | D70: 114003 | E70: Staples | F70: Storable Product | G70: ลูกแม็กขาคู่รุ่น410J ขนาด 4x10 | H70: Staples Double pin model 416J, size 4x10 | I70: กล่อง | J70: BOX | L70: =IFERROR(VLOOKUP(K70,'Supplier list'!B:C,2,0),"") | M70: Not Sellable | O70: 93
A71: Standard | B71: FS-FUFIT-013 | C71: 114003 | D71: 114003 | E71: Power plug | F71: Storable Product | G71: ปลั๊ก3ขา | H71: 3 pin plug | I71: ชิ้น | J71: PC | K71: AP-GDL000 | L71: =IFERROR(VLOOKUP(K71,'Supplier list'!B:C,2,0),"") -> หจก. กรีน ดิสทริบิวชั่น | M71: Not Sellable | O71: 28
A72: Standard | B72: FS-FUFIT-014 | C72: 114003 | D72: 114003 | E72: Power plug | F72: Storable Product | G72: ปลั๊ก2ขา | H72: 2 pin plug | I72: ชิ้น | J72: PC | K72: AP-GDL000 | L72: =IFERROR(VLOOKUP(K72,'Supplier list'!B:C,2,0),"") -> หจก. กรีน ดิสทริบิวชั่น | M72: Not Sellable | O72: 20
A73: Standard | B73: FS-FUFIT-015 | C73: 114003 | D73: 114003 | E73: Glue | F73: Storable Product | G73: กาวลาเท็กซ์ 32 ออน 12ขวด/ลัง | H73: Latex Glue 32 ounces, 12 bottles/box | I73: ขวด | J73: BOTTLES | K73: AP-KSR001 | L73: =IFERROR(VLOOKUP(K73,'Supplier list'!B:C,2,0),"") | M73: Not Sellable | O73: 55
A74: Standard | B74: FS-FUFIT-016 | C74: 114003 | D74: 114003 | E74: Chalk | F74: Storable Product | G74: ชอล์กTOUTH-UPSTLCK NO.101 | H74: Chalk TOUTH-UPSTTLCK NO.101 | I74: แท่ง | J74: STICK | K74: AP-MKW000 | L74: =IFERROR(VLOOKUP(K74,'Supplier list'!B:C,2,0),"") -> บริษัท เอ็มเค วู้ดเทค จำกัด | M74: Not Sellable | O74: 80
A75: Standard | B75: FS-FUFIT-017 | C75: 114003 | D75: 114003 | E75: Chalk | F75: Storable Product | G75: ชอล์กTOUTH-UPSTLCK NO.106 | H75: Chalk TOUTH-UPSTTLCK NO.106 | I75: แท่ง | J75: STICK | K75: AP-MKW000 | L75: =IFERROR(VLOOKUP(K75,'Supplier list'!B:C,2,0),"") -> บริษัท เอ็มเค วู้ดเทค จำกัด | M75: Not Sellable | O75: 80
...

Sheet Supplier list
B1: Code | C1: Name | D1: Street | E1: Street2 | F1: City | G1: City Old | H1: State Old | I1: Country | J1: Zip Code | K1: Company Phone | L1: Email | M1: Tax-ID | N1: Account Receivable | O1: Account Payable | P1: Branch | Q1: Note | R1: payment terms | S1: contact name | T1: contact phone | U1: Credit | V1: discount | W1: credit limit amount | X1: debit limit amount | Y1: account number | Z1: Supplier Rank
A2: 1 | B2: AP-9889000 | C2: บริษัท 9889 Thailnd | D2: 51/44 หมู่ที่4 ต.นาดี | F2: =CONCATENATE(G2,", ",H2) -> อ.เมือง, จ.สมุทรสาคร | G2: อ.เมือง | H2: จ.สมุทรสาคร | I2: Thailand | J2: 74000 | K2: 034-441-398 | L2: sales@9889.co.th | M2: 0105553040468 | P2: สำนักงานใหญ่ | Q2: จำหน่ายอุปกรณ์ตกแต่งภายในที่อยู่อาศัย และเฟอร์นิเจอร์ | S2: คุณแนน | T2: 087-9889-389 | U2: 30 DAYS | Z2: 1
B3: AP-AFA000 | C3: บริษัท เฟรมอลูมิเนียม เฟอร์นิเจอร์ แอนด์ ดีไซด์ จำกัด | D3: 100/102 ซ.พระยามนธาตุราชศรีพิจิตร แยก 29 แขวงคลองบางบอน | F3: =CONCATENATE(G3,", ",H3) -> เขตบางบอน, จ.กรุงเทพฯ | G3: เขตบางบอน | H3: จ.กรุงเทพฯ | I3: Thailand | J3: 10150 | K3: 098-010-6976 | L3: sales@alcustom48@gmail.com | M3: 0105562149744 | P3: สำนักงานใหญ่ | Q3: การผลิตอะลูมิเนียมและผลิตภัณฑ์อะลูมิเนียม | S3: คุณนลิน | T3: - | U3: 0 DAYS | Z3: 1
B4: AP-AGF000 | C4: บริษัท อะโกร ไฟเบอร์ จำกัด | D4: เลขที่ 138 หมู่ 7 ต.ท่าตูม | F4: =CONCATENATE(G4,", ",H4) -> อ.ศรีมหาโพธิ, จ.ปราจีนบุรี | G4: อ.ศรีมหาโพธิ | H4: จ.ปราจีนบุรี | I4: Thailand | J4: 25140 | K4: 038-538-347 | L4: Mkt.agrofiber@gmail.com | M4: 0255547000319 | P4: สำนักงานใหญ่ | Q4: การผลิตแผ่นไม้บางและผลิตภัณฑ์ไม้ | S4: - | T4: - | U4: 30 DAYS | Z4: 1
B5: AP-ALL000 | C5: บริษัท ออล อินดัสตรี เคม จำกัด | D5: 68/40 ซ.นวลน้อย แขวงคลองตันเหนือ | F5: =CONCATENATE(G5,", ",H5) -> เขตวัฒนา, จ.กรุงเทพฯ | G5: เขตวัฒนา | H5: จ.กรุงเทพฯ | I5: Thailand | J5: 10110 | K5: 02-7114458 | L5: admin@allindustrychem.com | M5: 0105551084930 | P5: สำนักงานใหญ่ | Q5: การผลิตเคมีภัณฑ์อนินทรีย์ขั้นมูลฐานอื่น ๆ | S5: คุณฉัตรชัย | T5: 081-9076035 | U5: 30 DAYS | Z5: 1
B6: AP-AMJ000 | C6: Amjay Exports Private Limited | D6: 114 B, Pocket-6, Mayur Vihar Phase-3, | F6: =CONCATENATE(G6,", ",H6) -> New Delhi, Delhi | G6: New Delhi | H6: Delhi | I6: India | J6: 110096 | K6: +91-99102-13095 | L6: mlg@amjayexp.com | M6: AAKCA5721B | P6: สำนักงานใหญ่ | S6: K.Moti | T6: +91-11-22616379 | U6: 0 DAYS | Z6: 1
B7: AP-ARN000 | C7: บริษัท อารีนาเทค จำกัด | D7: 40/134 หมู่ที่14 ต.บางแก้ว | F7: =CONCATENATE(G7,", ",H7) -> อ.บางพลี, จ.สมุทรปราการ | G7: อ.บางพลี | H7: จ.สมุทรปราการ | I7: Thailand | J7: 10540 | K7: 02-334-0996 | L7: arenatech21@gmail.com | M7: 0115564011642 | P7: สำนักงานใหญ่ | S7: คุณเมธวี | T7: 065-0598798 | U7: 0 DAYS | Z7: 1
B8: AP-ASC000 | C8: บริษัท เอเชี่ยน ไซเอนติฟิค จำกัด | D8: 199/1กม.10ม.3ซ.วงษ์แพทย์ถ.เทพารักษ์ ต.บางพลีใหญ่ | F8: =CONCATENATE(G8,", ",H8) -> อ.บางพลี, จ.สมุทรปราการ | G8: อ.บางพลี | H8: จ.สมุทรปราการ | I8: Thailand | J8: 10540 | K8: 02-7574515 | L8: sales@asc-th.com | M8: 0105537002964 | P8: สำนักงานใหญ่ | S8: คุณนุช | T8: ต่อ 105 | U8: 0 DAYS | Z8: 1
B9: AP-ASO000 | C9: บริษัท แอสเซนท์ คอนสตรัคชั่น ซัพพลาย จำกัด | D9: 138/25 ซอยสายไหม 34 (พัธนชัย) ถนนสายไหม แขวงสายไหม | F9: =CONCATENATE(G9,", ",H9) -> เขตสายไหม, จ.กรุงเทพฯ | G9: เขตสายไหม | H9: จ.กรุงเทพฯ | I9: Thailand | J9: 10220 | K9: 02-9915109 | L9: - | M9: 0105556168392 | P9: สำนักงานใหญ่ | S9: - | T9: - | U9: 30 DAYS | Z9: 1
B10: AP-BDM000 | C10: บริษัท ตราเพชร จำกัด | D10: 87 หมู่ 10 ถ.ปู่เจ้าสมิงพราย ต.สำโรงใต้ | F10: =CONCATENATE(G10,", ",H10) -> อ.พระประแดง, จ.สมุทรปราการ | G10: อ.พระประแดง | H10: จ.สมุทรปราการ | I10: Thailand | J10: 10130 | K10: 02-757-6100 | L10: - | M10: 0105516008670 | P10: สำนักงานใหญ่ | S10: คุณจิราวัฒน์ | T10: 097-424-5524 | U10: 60 DAYS | Z10: 1
B11: AP-BES000 | C11: บริษัท เบสต้า กู้ด โปร จำกัด | D11: 103/2 หมู่ 6 ต.บางพลี | F11: =CONCATENATE(G11,", ",H11) -> อ.บางพลี, จ.สมุทรปราการ | G11: อ.บางพลี | H11: จ.สมุทรปราการ | I11: Thailand | J11: 10540 | K11: 02-337-3401-3 | L11: sales@bestapaint.com | M11: 0115547002959 | P11: สำนักงานใหญ่ | Q11: ผลิตและจำหน่ายสีน้ำมัน,สีทา,สีเคลือบ,สีพ่นรับจ้างพ่นสี | S11: - | T11: - | U11: 15 DAYS | V11: 0.2 | Z11: 1
B12: AP-BEST00 | C12: Best Solid Surfaces Corp. | D12: Xishan Economic Developent Zone | F12: =CONCATENATE(G12,", ",H12) -> Wuxi, Jiangsu | G12: Wuxi | H12: Jiangsu | I12: China | J12: 214101 | K12: - | L12: - | M12: - | P12: สำนักงานใหญ่ | S12: - | T12: - | U12: 0 DAYS | Z12: 1
B13: AP-BKM000 | C13: บริษัท บางกอก มาสเตอร์ จำกัด | D13: 276 ซ. อ่อนนุช 35 ถ.อ่อนนุช แขวงสวนหลวง | F13: =CONCATENATE(G13,", ",H13) -> เขตสวนหลวง, กรุงเทพมหานคร | G13: เขตสวนหลวง | H13: กรุงเทพมหานคร | I13: Thailand | J13: 10250 | K13: 02-721-5238 | L13: - | M13: - | P13: สำนักงานใหญ่ | S13: - | T13: - | U13: 0 DAYS | Z13: 1
B14: AP-BPP000 | C14: บริษัท บางพลี แพค (บีพีพี) จำกัด | D14: 113/7 หมู่ 7 ต.บางพลีใหญ่ | F14: =CONCATENATE(G14,", ",H14) -> อ.บางพลี, จ.สมุทรปราการ | G14: อ.บางพลี | H14: จ.สมุทรปราการ | I14: Thailand | J14: 10540 | K14: 02-070-1133 | L14: - | M14: 0115559004196 | P14: สำนักงานใหญ่ | Q14: ผลิตและจัดจำหน่ายน้ำดื่ม | S14: - | T14: - | U14: 0 DAYS | Z14: 1
B15: AP-BTV000 | C15: บริษัท บุญถาวรเซรามิค จำกัด | D15: 15/2 หมู่ที่ 14 ถ.บางนาตราด ต.บางพลีใหญ่ | F15: =CONCATENATE(G15,", ",H15) -> อ.บางพลี, จ.สมุทรปราการ | G15: อ.บางพลี | H15: จ.สมุทรปราการ | I15: Thailand | J15: 10540 | K15: 02-1746888 | L15: CONTACT_CENTER@BOONTHAVORN.COM | M15: 0105535130116 | P15: สำนักงานใหญ่ | Q15: กระเบื้องเซรามิค,สุขภัณฑ์,เฟอร์นิเจอร์,ชุดครัว,หินอ่อน,หินแกรนิต | S15: - | T15: - | U15: 0 DAYS | Z15: 1
B16: AP-BUC001 | C16: ร้าน บุญช่วยรุ่งเรืองค้าไม้ | D16: 44หมู่6 ต.บางเพรียง | F16: =CONCATENATE(G16,", ",H16) -> อ.บางบ่อ, จ.สมุทรปราการ | G16: อ.บางบ่อ | H16: จ.สมุทรปราการ | I16: Thailand | J16: 10560 | K16: 085-0216907,086-2311185 | L16: - | M16: - | P16: สำนักงานใหญ่ | S16: - | T16: - | U16: 0 DAYS | Z16: 1
B17: AP-BUI000 | C17: บริษัท บลู อินเตอร์เนชั่นแนล จำกัด | D17: 8,10,12ซ.รามคำแหง26/1 ถ.รามคำแหง แขวงหัวหมาก | F17: =CONCATENATE(G17,", ",H17) -> เขตบางกะปิ, กรุงเทพมหานคร | G17: เขตบางกะปิ | H17: กรุงเทพมหานคร | I17: Thailand | J17: 10240 | K17: 02-3747744 | L17: - | M17: 0105524001824 | P17: สำนักงานใหญ่ | S17: คุณสมชาย | T17: 084-639-5142 | U17: 30 DAYS | V17: 0.2 | Z17: 1
B18: AP-CAG000 | C18: บริษัท ฉัตรเกศ จำกัด | D18: 61/9 หมู่9 ถ.เทพารักษ์ ต.บางพลีใหญ่ | F18: =CONCATENATE(G18,", ",H18) -> อ.บางพลี, จ.สมุทรปราการ | G18: อ.บางพลี | H18: จ.สมุทรปราการ | I18: Thailand | J18: 10540 | K18: 02-7505880 | L18: - | M18: 0105535095736 | P18: สำนักงานใหญ่ | S18: - | T18: - | U18: 0 DAYS | Z18: 1
B19: AP-CBO000 | C19: ซีโบ เจเนรัล แอนด์ ซัพพลาย | D19: 189/331 ม.6 ต.แพรกษา | F19: =CONCATENATE(G19,", ",H19) -> อ.เมืองสมุทรปราการ, จ.สมุทรปราการ | G19: อ.เมืองสมุทรปราการ | H19: จ.สมุทรปราการ | I19: Thailand | J19: 10280 | K19: 086-5657004 | L19: chiraphat.koi@gmail.com | M19: 3250400406597 | P19: สำนักงานใหญ่ | S19: - | T19: - | U19: 0 DAYS | Z19: 1
B20: AP-CCG000 | C20: บริษัท เซ็นทรัล เคมีคอล 1999 กรุ๊ป จำกัด | D20: 884/1 หมู่ 7 ต.บางปูใหม่ | F20: =CONCATENATE(G20,", ",H20) -> อ.เมืองสมุทรปราการ, จ.สมุทรปราการ | G20: อ.เมืองสมุทรปราการ | H20: จ.สมุทรปราการ | I20: Thailand | J20: 10280 | K20: 02-0699776 | L20: - | M20: 0115555021657 | P20: สำนักงานใหญ่ | S20: คุณแป้ง | T20: 086-334-5087 | U20: 30 DAYS | Z20: 1
B21: AP-CE9000 | C21: บริษัท เจริญอิเล็กทริค999 จำกัด | D21: 49/174 หมู่ 6 ต.บางโพ | F21: =CONCATENATE(G21,", ",H21) -> -, จ.นนทบุรี | G21: - | H21: จ.นนทบุรี | I21: Thailand | J21: 11110 | K21: 094-928-9009 | L21: arnat033@gmail.com | M21: 0105560118949 | P21: สำนักงานใหญ่ | S21: - | T21: - | U21: 0 DAYS | Z21: 1
B22: AP-CHE000 | C22: บริษัท ฉิ้นฮง เอ็นเตอร์ไพรส์ จำกัด | D22: 2 ซอยฉลองกรุง 53 ถนนฉลองกรุง แขวงลำปลาทิว | F22: =CONCATENATE(G22,", ",H22) -> เขตลาดกระบัง, กรุงเทพมหานคร | G22: เขตลาดกระบัง | H22: กรุงเทพมหานคร | I22: Thailand | J22: 10520 | K22: 02-3605087-88 | L22: - | M22: 0105546037252 | P22: สำนักงานใหญ่ | S22: - | T22: - | U22: 30 DAYS | Z22: 1
B23: AP-CHNM00 | C23: Chanzhou Huaeri New Material.co.,Ltd. | D23: NO.2DONGGANG ROND 3 XINBEI DISTRICT | F23: =CONCATENATE(G23,", ",H23) -> Changzhou, Jiangsu | G23: Changzhou | H23: Jiangsu | I23: China | J23: 213127 | K23: - | L23: - | M23: - | P23: สำนักงานใหญ่ | S23: - | T23: - | U23: 0 DAYS | Z23: 1
B24: AP-CIT000 | C24: บริษัท ซิตี้อาร์ตอลูมิเนียมเวอร์ค จำกัด | D24: 56/56 ถ.พระราม 1 แขวงรองเมือง | F24: =CONCATENATE(G24,", ",H24) -> เขตปทุมวัน, กรุงเทพมหานคร | G24: เขตปทุมวัน | H24: กรุงเทพมหานคร | I24: Thailand | J24: 10330 | K24: 02-2151512 | L24: contact@cityart.co.th | M24: 0105531054989 | P24: สำนักงานใหญ่ | S24: - | T24: - | U24: 0 DAYS | Z24: 1
B25: AP-CPS000 | C25: บริษัท ซีพีเอส สเปเซียลตี้ จำกัด | D25: 111/213 หมู่ 8 ถ.ฉลองกรุง แขวงลำปลาทิว | F25: =CONCATENATE(G25,", ",H25) -> เขตลาดกระบัง , กรุงเทพมหานคร | G25: เขตลาดกระบัง | H25: กรุงเทพมหานคร | I25: Thailand | J25: 10520 | K25: 02-7381855 | L25: - | M25: 0135562022400 | P25: สำนักงานใหญ่ | S25: คุณสุวรรณา | T25: - | U25: 0 DAYS | Z25: 1
B26: AP-CPTCP00 | C26: บริษัท แคปิตอล คาร์เปท จำกัด | D26: 32 ซอยอุดมสุข31 แขวงบางจาก | F26: =CONCATENATE(G26,", ",H26) -> เขตพระโขนง , กรุงเทพมหานคร | G26: เขตพระโขนง | H26: กรุงเทพมหานคร | I26: Thailand | J26: 10260 | K26: 02-3838850 | L26: capitalcarpet@hotmail.com,32capital@gmail.com | M26: 0105545076939 | P26: สำนักงานใหญ่ | S26: คุณโก๋ | T26: 081-934-5150 | U26: 0 DAYS | Z26: 1
B27: AP-CRC000 | C27: บริษัท ซีอาร์ซี ไทวัสดุ | D27: 11/15 หมู่ที่ 9 ตำบลบางปลา | F27: =CONCATENATE(G27,", ",H27) -> อ.บางพลี, จ.สมุทรปราการ | G27: อ.บางพลี | H27: จ.สมุทรปราการ | I27: Thailand | J27: 10540 | K27: 02-101-2500 | L27: - | M27: 0105555021215 | P27: สำนักงานใหญ่ | S27: - | T27: - | U27: 0 DAYS | Z27: 1
B28: AP-CRC001 | C28: บริษัท ซีอาร์ซี ไทวัสดุ จำกัด (สาขาบางนา) | D28: 54 หมู่ที่ 13 ตำบลบางแก้ว | F28: =CONCATENATE(G28,", ",H28) -> อำเภอบางพลี, จ.สมุทรปราการ | G28: อำเภอบางพลี | H28: จ.สมุทรปราการ | I28: Thailand | J28: 10540 | K28: 02-101-2500 | L28: - | M28: 0105555021215 | P28: สำนักงานใหญ่ | S28: - | T28: - | U28: 0 DAYS | Z28: 1
B29: AP-CSG000 | C29: บริษัท ซี.เอส.กลาส โพลิชชิ่ง | D29: 33/21 หมู่ที่ 7 ตำบลบางพลีใหญ่ | F29: =CONCATENATE(G29,", ",H29) -> อ.บางพลี, จ.สมุทรปราการ | G29: อ.บางพลี | H29: จ.สมุทรปราการ | I29: Thailand | J29: 10540 | K29: 02-7064394 | L29: - | M29: 0115557001661 | P29: สำนักงานใหญ่ | S29: - | T29: 086-334-8482 | U29: 0 DAYS | Z29: 1
... B80: AP-IYR000 | C80: บริษัท ไอยรา เลเซอร์ ปริ้นท์ จำกัด | D80: 641/90 ถ.อนามัยงามเจริญ แขวงท่าข้าม | F80: =CONCATENATE(G80,", ",H80) -> เขตบางขุนเทียน, กรุงเทพมหานคร | G80: เขตบางขุนเทียน | H80: กรุงเทพมหานคร | I80: Thailand | J80: 10150 | K80: 02-4083465 | L80: - | M80: 0105560004277 | P80: สำนักงานใหญ่ | S80: - | T80: - | U80: 30 DAYS | Z80: 1
B81: AP-JBA000 | C81: บริษัท จัมโบ้เอ อินดัสทรี จำกัด | D81: 23 ม.4 ถ.ติวานนท์ ต.บ้านใหม่ | F81: =CONCATENATE(G81,", ",H81) -> อ.ปากเกร็ด, จ.นนทบุรี | G81: อ.ปากเกร็ด | H81: จ.นนทบุรี | I81: Thailand | J81: 11120 | K81: 086-3050534 | L81: - | M81: 0125534000774 | P81: สำนักงานใหญ่ | Q81: การผลิตโซ่ ลวดสปริง สลักเกลียว และตะปูควง | S81: - | T81: - | U81: 0 DAYS | Z81: 1
B82: AP-JIB000 | C82: บริษัท เจ ไอ บี คอมพิวเตอร์ กรุ๊ป จำกัด | D82: 21 ถ.พหลโยทิน แขวงสนามบิน | F82: =CONCATENATE(G82,", ",H82) -> เขตดอนเมือง, กรุงเทพมหานคร | G82: เขตดอนเมือง | H82: กรุงเทพมหานคร | I82: Thailand | J82: 10210 | K82: 02-7912000 | L82: - | M82: 0135544005281 | P82: สำนักงานใหญ่ | Q82: จำหน่ายคอมพิวเตอร์และอุปกรณ์ที่เกี่ยวข้อง | S82: - | T82: - | U82: 0 DAYS | Z82: 1
B83: AP-JNE000 | C83: บริษัท เจ แนค จำกัด | D83: 339/107 ม.5 ซ.คลองอาเสี่ย ถ.พุทธรักษา ต.แพรกษาใหม่ | F83: =CONCATENATE(G83,", ",H83) -> อ.เมือง, จ.สมุทรปราการ | G83: อ.เมือง | H83: จ.สมุทรปราการ | I83: Thailand | J83: 10280 | K83: 0800161700 | L83: info@jnac.co.th. ,jnac.co.th@gmail.com | M83: 0115553004976 | P83: สำนักงานใหญ่ | Q83: กระดาษทราย จานทรายซ้อน ใบเจียร ใบตัด วัสดุปรับปรุงอาคารและอุปกรณ์ งานขัด ตัด เจาะ เจียร ทุกชนิด | S83: - | T83: - | U83: 0 DAYS | Z83: 1
B84: AP-JPR000 | C84: ร้าน จั่นเพชร รีไซเคิล | D84: 999/8 ม.2 ต.บางปูใหม่ | F84: =CONCATENATE(G84,", ",H84) -> อ.เมือง, จ.สมุทรปราการ | G84: อ.เมือง | H84: จ.สมุทรปราการ | I84: Thailand | J84: 10280 | K84: 02-7095518 | L84: - | M84: - | P84: สำนักงานใหญ่ | S84: คุณนพ | T84: 083-456-7918 | U84: 0 DAYS | Z84: 1
B85: AP-JRP000 | C85: หจก. เจอาร์พีฟลอร์ จำกัด | D85: 108/256 ซ.เฉลิมพระเกียรติ ร.9 แยก28 แขวงดอกไม้ | F85: =CONCATENATE(G85,", ",H85) -> เขตประเวศ, กรุงเทพมหานคร | G85: เขตประเวศ | H85: กรุงเทพมหานคร | I85: Thailand | J85: 10250 | K85: 089-840-2251 | L85: y.jeerasak@hotmail.com | M85: 0103560010666 | P85: สำนักงานใหญ่ | Q85: การก่อสร้างอาคารที่ไม่ใช่ที่พักอาศัย | S85: - | T85: - | U85: 0 DAYS | Z85: 1
B86: AP-JSM000 | C86: บริษัท เจ เอส เมคคานิค จำกัด | D86: 52/10 ม. ถ.เทพกาญจนา ต.คอกกระบือ | F86: =CONCATENATE(G86,", ",H86) -> อ.เมือง, จ.สมุทรสาคร | G86: อ.เมือง | H86: จ.สมุทรสาคร | I86: Thailand | J86: 74000 | K86: 034-441114 | L86: jsm_online@jsmechanic.co.th | M86: 0105545092055 | P86: สำนักงานใหญ่ | Q86: กระดาษทราย | S86: คุณกระแต | T86: 087-496-7865 | U86: 0 DAYS | Z86: 1
B87: AP-K&MAG00 | C87: K&MAG MACHINERY CO.,LTD | D87: No.2,west 8 Road,Jiangcun,Leliu,Shunde, | F87: =CONCATENATE(G87,", ",H87) -> Foshan, Guangdong | G87: Foshan | H87: Guangdong | I87: China | J87: 528322 | K87: - | L87: - | M87: - | P87: สำนักงานใหญ่ | S87: - | T87: - | U87: 0 DAYS | Z87: 1
B88: AP-KAK000 | C88: บริษัท โกรว์ แอนด์ โกลว์ จำกัด | D88: 120/408 ม. 4 ซ. อุ่นอารี ถ. พุทธรักษา ต. ท้ายบ้านใหม่ | F88: =CONCATENATE(G88,", ",H88) -> อ.เมืองสมุทรปราการ, จ.สมุทรปราการ | G88: อ.เมืองสมุทรปราการ | H88: จ.สมุทรปราการ | I88: Thailand | J88: 10280 | K88: 02-3827432 | L88: - | M88: 0115533000428 | P88: สำนักงานใหญ่ | Q88: รับจ้างทากาวผ้า หนัง ฟองน้ำ สำหรับทำเครื่องหนังทุกชนิด | S88: คุณโอ๋ | T88: - | U88: 30 DAYS | Z88: 1
B89: AP-KBK000 | C89: บริษัท คิงบางกอก อินเตอร์เทรด จำกัด | D89: 69/9-11 หมู่ 7 ถนนรามอินทรา กม 4 แขวงท่าแร้ง | F89: =CONCATENATE(G89,", ",H89) -> เขตบางเขน , กรุงเทพมหานคร | G89: เขตบางเขน | H89: กรุงเทพมหานคร | I89: Thailand | J89: 10220 | K89: 02-5093850 | L89: kingproshop.official@gmail.com | M89: 0105545012035 | P89: สำนักงานใหญ่ | Q89: จำหน่ายและติดตั้งเครื่องใช้ไฟฟ้าทุกชนิด | S89: คุณมุ่น | T89: - | U89: 30 DAYS | Z89: 1
B90: AP-KIG000 | C90: บริษัท เค อินฟินิตี้ กรุ๊ป จำกัด(สำนักงานใหญ่) | D90: 47/76 ม.5 ต.ไร่ขิง | F90: =CONCATENATE(G90,", ",H90) -> อ.สามพราน, จ.นครปฐม | G90: อ.สามพราน | H90: จ.นครปฐม | I90: Thailand | J90: 73210 | K90: 098-6152996 | L90: Kinfinitygroup@Gmail.Com | M90: 0735564000149 | P90: สำนักงานใหญ่ | S90: คุณก้อย | T90: - | U90: 0 DAYS | Z90: 1
...

Sheet Category
A1: Product Category
A2: Tape
A3: buy-sell
A4: Service
A5: Carpet
A6: Cardboard cylinder
A7: Honeycomb
A8: Tool
A9: Sandpaper
A10: Battery
A11: Drill bits
A12: Light bulb
... A179: Non Standard

Sheet Accounts
A1: Product Account
A2: 513010
A3: 513010
A4: 513010
A5: 513010
A6: 513010
A7: 513010
A8: 513010
A9: 513010
A10: 513010
A11: 513025
A12: 513025
A13: 513025
... A1709: 513004

Sheet UOM
A1: UOM EN
A2: PC
A3: JOB
A4: SQM
A5: SHEET
A6: TUBE
A7: SET
A8: BOX
A9: BOTTLES
A10: STRIP
A11: ROLL
A12: PANEL
... A32: DISK

Sheet Country
A1: Country
A3: Thailand
A4: Thailand
A5: Thailand
A6: Thailand
A7: India
A8: Thailand
A9: Thailand
A10: Thailand
A11: Thailand
A12: Thailand
A13: China
... A621: Thailand

Sheet Payment Terms
A1: Credit
A2: 30 DAYS
A3: 0 DAYS
A4: 60 DAYS
A5: 15 DAYS
A6: 7 DAYS
A7: 90 DAYS

Sheet Product 1-651
A1: Standardize | B1: Product Code | C1: Income Account | D1: Expense Account | E1: Product Category | F1: Product Type | G1: Product Name TH | H1: Product Name EN | I1: UOM TH | J1: UOM EN | K1: Code Supplier | L1: Supplier Name | M1: True/False | N1: Selling Price | O1: Cost Price
A2: Standard | B2: AX-3M233-TH | C2: 513010 | D2: 513010 | E2: Tape | F2: Storable Product | G2: เทปกาว 3M | H2: Masking tape | I2: ชิ้น | J2: PC | K2: AP-CST000 | L2: =IFERROR(VLOOKUP(K2,'Supplier list'!B:C,2,0),"") | M2: =FALSE() -> 0 | O2: 202
A3: Standard | B3: AX-513004-TH | C3: 513010 | D3: 513010 | E3: buy-sell | F3: Storable Product | G3: ซื้อมา-ขายไป | H3: Buy-Sell | I3: ชิ้น | J3: PC | K3: - | L3: =IFERROR(VLOOKUP(K3,'Supplier list'!B:C,2,0),"") | M3: =FALSE() -> 0 | O3: 0
A4: Standard | B4: AX-513006-TH | C4: 513010 | D4: 513010 | E4: Service | F4: Storable Product | G4: ค่าใช้จ่าย-นำเข้า | H4: Import Fee | I4: งาน | J4: JOB | K4: - | L4: =IFERROR(VLOOKUP(K4,'Supplier list'!B:C,2,0),"") | M4: =FALSE() -> 0 | O4: 0
A5: Standard | B5: AX-513007-TH | C5: 513010 | D5: 513010 | E5: Service | F5: Storable Product | G5: ค่าใช้จ่าย-ส่งออก | H5: Export Fee | I5: งาน | J5: JOB | K5: - | L5: =IFERROR(VLOOKUP(K5,'Supplier list'!B:C,2,0),"") | M5: =FALSE() -> 0 | O5: 0
A6: Standard | B6: AX-531016-TH | C6: 513010 | D6: 513010 | E6: Service | F6: Storable Product | G6: ค่าสวัสดิการอื่นๆ-เลี้ยงข้าวพนักงาน | H6: Other welfare expenses - food for employees | I6: งาน | J6: JOB | K6: - | L6: =IFERROR(VLOOKUP(K6,'Supplier list'!B:C,2,0),"") | M6: =FALSE() -> 0 | O6: 0
A7: Standard | B7: AX-CGM00-TH | C7: 513010 | D7: 513010 | E7: Tape | F7: Storable Product | G7: เทปกาว | H7: Masking tape | I7: ชิ้น | J7: PC | K7: AP-BNT000 | L7: =IFERROR(VLOOKUP(K7,'Supplier list'!B:C,2,0),"") | M7: =FALSE() -> 0 | O7: 84
A8: Standard | B8: AX-PH007-TH | C8: 513010 | D8: 513010 | E8: Carpet | F8: Storable Product | G8: พื้นพรมแผ่นรุ่น PH07 | H8: Carpet floor sheet model PH07 | I8: ตรม. | J8: SQM | K8: AP-SFL000 | L8: =IFERROR(VLOOKUP(K8,'Supplier list'!B:C,2,0),"") | M8: =FALSE() -> 0 | O8: 680
A9: Standard | B9: AX-PT00-001 | C9: 513010 | D9: 513010 | E9: Cardboard cylinder | F9: Storable Product | G9: Paper Tube/กระบอกภาชนะกระดาษแข็ง | H9: Cardboard cylinder with spray paint | I9: ชิ้น | J9: PC | K9: AP-QNL000 | L9: =IFERROR(VLOOKUP(K9,'Supplier list'!B:C,2,0),"") -> CO.,LTD QINGDAO NEW LIBERTY INT'L TRADING CO.LTD. | M9: =FALSE() -> 0 | O9: 0.35
A10: Standard | B10: AX-PT00-002 | C10: 513010 | D10: 513010 | E10: Service | F10: Storable Product | G10: ค่าส่งสินค้าอื่นๆ | H10: Other shipping costs | I10: งาน | J10: JOB | K10: - | L10: =IFERROR(VLOOKUP(K10,'Supplier list'!B:C,2,0),"") | M10: =FALSE() -> 0 | O10: 0
A11: Standard | B11: FC-0001 | C11: 513025 | D11: 513025 | E11: Honeycomb | F11: Storable Product | G11: กระดาษรังผึ้ง honeycomb กว้าง60xยาว30 หนา10 cm. | H11: Honey Comb 60x30x10 cm. | I11: ชิ้น | J11: PC | K11: AP-QNL000 | L11: =IFERROR(VLOOKUP(K11,'Supplier list'!B:C,2,0),"") -> CO.,LTD QINGDAO NEW LIBERTY INT'L TRADING CO.LTD. | M11: =FALSE() -> 0 | O11: 5.7
A12: Standard | B12: FC-0002 | C12: 513025 | D12: 513025 | E12: Tool | F12: Storable Product | G12: เครื่องเจียร์ไฟฟ้า 4" MAKITA 9500NB | H12: Electric Grinder 4MAKITA9500NB" | I12: ชิ้น | J12: PC | K12: AP-GDL000 | L12: =IFERROR(VLOOKUP(K12,'Supplier list'!B:C,2,0),"") -> หจก. กรีน ดิสทริบิวชั่น | M12: =FALSE() -> 0 | O12: 2990
A13: Standard | B13: FC-0003 | C13: 513025 | D13: 513025 | E13: Tool | F13: Storable Product | G13: ถังกาพ่น M-871 | H13: Spray Gun M-871 | I13: ชิ้น | J13: PC | K13: - | L13: =IFERROR(VLOOKUP(K13,'Supplier list'!B:C,2,0),"") | M13: =FALSE() -> 0 | O13: 4200
... A23: Standard | B23: FC-0013 | C23: 513025 | D23: 513025 | E23: Light bulb | F23: Storable Product | G23: หลอดไฟ (ยาว) | H23: Light bulb (long) | I23: หลอด | J23: TUBE | K23: AP-TPK001 | L23: =IFERROR(VLOOKUP(K23,'Supplier list'!B:C,2,0),"") -> บริษัท ที.พี.เค ไทยเมท แมชชีนทูลล์ จำกัด | M23: =FALSE() -> 0 | O23: 229
A24: Standard | B24: FC-0014 | C24: 513025 | D24: 513025 | E24: Light bulb | F24: Storable Product | G24: หลอดไฟ (สั้น) | H24: Light bulb (short) | I24: หลอด | J24: TUBE | L24: =IFERROR(VLOOKUP(K24,'Supplier list'!B:C,2,0),"") | M24: =FALSE() -> 0 | O24: 63
A25: Standard | B25: FC-0015 | C25: 513025 | D25: 513025 | E25: Tool | F25: Storable Product | G25: หัวปืน M-871 (จีน) | H25: Gun head M-871 (China) | I25: ชิ้น | J25: PC | K25: - | L25: =IFERROR(VLOOKUP(K25,'Supplier list'!B:C,2,0),"") | M25: =FALSE() -> 0 | O25: 0
A26: Standard | B26: FC-0016 | C26: 513025 | D26: 513025 | E26: Tool | F26: Storable Product | G26: หัวจี้ลม แกน 3 mm. | H26: Air pendant 3 mm. | I26: ชิ้น | J26: PC | K26: - | L26: =IFERROR(VLOOKUP(K26,'Supplier list'!B:C,2,0),"") | M26: =FALSE() -> 0 | O26: 0
A27: Standard | B27: FC-0017 | C27: 513025 | D27: 513025 | E27: Screw | F27: Storable Product | G27: สกรูมิลดำ 12x55+หัว+อีแปะ | H27: Hexagon Screw Black 12x55 | I27: ชุด | J27: SET | K27: AP-KSR001 | L27: =IFERROR(VLOOKUP(K27,'Supplier list'!B:C,2,0),"") -> บริษัท เกรียงศิริพัฒนา (1995) จำกัด | M27: =FALSE() -> 0 | O27: 15
A28: Standard | B28: FC-0020 | C28: 513025 | D28: 513025 | E28: Joint | F28: Storable Product | G28: คอปเปอร์ 3 ทาง T | H28: Coupler 3 Way Multi Pass ,T | I28: ชิ้น | J28: PC | K28: AP-KSR001 | L28: =IFERROR(VLOOKUP(K28,'Supplier list'!B:C,2,0),"") -> บริษัท เกรียงศิริพัฒนา (1995) จำกัด | M28: =FALSE() -> 0 | O28: 190
A29: Standard | B29: FC-0021 | C29: 513025 | D29: 513025 | E29: Joint | F29: Storable Product | G29: ข้อต่อคอปเปอร์ 20pm. | H29: Coupler joint, model 20PM | I29: ชิ้น | J29: PC | K29: AP-KSR001 | L29: =IFERROR(VLOOKUP(K29,'Supplier list'!B:C,2,0),"") -> บริษัท เกรียงศิริพัฒนา (1995) จำกัด | M29: =FALSE() -> 0 | O29: 20
A30: Standard | B30: FC-0023 | C30: 513025 | D30: 513025 | E30: Drill bits | F30: Storable Product | G30: ดอกเจาะกระจก 8มม. | H30: Glass drill bit 8 mm. | I30: ชิ้น | J30: PC | K30: AP-KSR001 | L30: =IFERROR(VLOOKUP(K30,'Supplier list'!B:C,2,0),"") -> บริษัท เกรียงศิริพัฒนา (1995) จำกัด | M30: =FALSE() -> 0 | O30: 200
A31: Standard | B31: FC-0024 | C31: 513025 | D31: 513025 | E31: Battery | F31: Storable Product | G31: 005.23.601 BRUSH ET-BG 240V CT26/36 | H31: 005.23.601 BRUSH ET-BG 240V CT26/36 | I31: ชิ้น | J31: PC | K31: AP-HAF001 | L31: =IFERROR(VLOOKUP(K31,'Supplier list'!B:C,2,0),"") -> บริษัท เฮเฟเล่ (ประเทศไทย) จำกัด | M31: =FALSE() -> 0 | O31: 1776
A32: Standard | B32: FC-0026 | C32: 513025 | D32: 513025 | E32: Wheel | F32: Storable Product | G32: ล้อไนลอนขาวชุดชุบโครเมียม แป้นเป็น 4" | H32: Wheels, white nylon, chrome plated set, backplate 4" | I32: กล่อง | J32: BOX | K32: AP-KCR000 | L32: =IFERROR(VLOOKUP(K32,'Supplier list'!B:C,2,0),"") | M32: =FALSE() -> 0 | O32: 435
A33: Standard | B33: FC-0027 | C33: 513025 | D33: 513025 | E33: Bathroom cleaner | F33: Storable Product | G33: น้ำยาล้างห้องน้ำ (เป็ดโปร) | H33: Bathroom cleaner (Duck Pro) | I33: ขวด | J33: BOTTLES | K33: AP-SMK000 | L33: =IFERROR(VLOOKUP(K33,'Supplier list'!B:C,2,0),"") -> บริษัท สยามแม็คโคร จำกัด (มหาชน) | M33: =FALSE() -> 0 | O33: 209
A34: Standard | B34: FC-0028 | C34: 513025 | D34: 513025 | E34: Screw | F34: Storable Product | G34: สกรูมิล JF M4x8-0.70 | H34: Hexagon Screw JF M4x8-0.70 | I34: ชิ้น | J34: PC | K34: AP-KCR000 | L34: =IFERROR(VLOOKUP(K34,'Supplier list'!B:C,2,0),"") -> บริษัท ก.เจริญฮาร์ดแวร์ จำกัด | M34: =FALSE() -> 0 | O34: 0.25
A35: Standard | B35: FC-0029 | C35: 513025 | D35: 513025 | E35: Drill bits | F35: Storable Product | G35: โฮลซอเจาะไม้ 7 ใบ/ชุด 26-63มม. | H35: Hole Saw 7 wood drill bits/set 26-63mm. | I35: ชุด | J35: SET | K35: AP-SHM000 | L35: =IFERROR(VLOOKUP(K35,'Supplier list'!B:C,2,0),"") -> บริษัท ซูเปอร์โฮมมาร์ท จำกัด (สำนักงานใหญ่) | M35: =FALSE() -> 0 | O35: 115
A36: Standard | B36: FC-0030 | C36: 513025 | D36: 513025 | E36: EPE Foam | F36: Storable Product | G36: EPE Foam Laminate inside (handle J) | H36: EPE Foam Laminate inside (handle J) | I36: ชิ้น | J36: PC | K36: AP-PCP000 | L36: =IFERROR(VLOOKUP(K36,'Supplier list'!B:C,2,0),"") | M36: =FALSE() -> 0 | O36: 4.5
... A63: Standard | B63: FS-FUFIT-002 | C63: 114003 | D63: 114003 | E63: Rubber Bump Button | F63: Storable Product | G63: 483.01.996 ปุ่มยางกันกระแทก | H63: 483.01.996 Rubber Bump Button | I63: แผง | J63: PANEL | K63: AP-HAF001 | L63: =IFERROR(VLOOKUP(K63,'Supplier list'!B:C,2,0),"") -> บริษัท เฮเฟเล่ (ประเทศไทย) จำกัด | M63: =FALSE() -> 0 | O63: 178
A64: Standard | B64: FS-FUFIT-003 | C64: 114003 | D64: 114003 | E64: Triangle Claw Bumper | F64: Storable Product | G64: กันชนก้ามปูสามเหลี่ยม BARCO | H64: BARCO Triangle Claw Bumper | I64: ชิ้น | J64: PC | L64: =IFERROR(VLOOKUP(K64,'Supplier list'!B:C,2,0),"") | M64: =FALSE() -> 0 | O64: 28
A65: Standard | B65: FS-FUFIT-004 | C65: 114003 | D65: 114003 | E65: Push Catches | F65: Storable Product | G65: กดเปิดหน้าบานแบบแม่เหล็ก XL | H65: Press to open the magnetic door XL | I65: ชิ้น | J65: PC | L65: =IFERROR(VLOOKUP(K65,'Supplier list'!B:C,2,0),"") | M65: =FALSE() -> 0 | O65: 68
A66: Standard | B66: FS-FUFIT-008 | C66: 114003 | D66: 114003 | E66: Staples | F66: Storable Product | G66: ลูกแม็กขาคู่รุ่น1010J ขนาด 10x10 | H66: Double leg alloy, model 1010J, size 10x10 | I66: กล่อง | J66: BOX | K66: AP-KSR001 | L66: =IFERROR(VLOOKUP(K66,'Supplier list'!B:C,2,0),"") | M66: =FALSE() -> 0 | O66: 100
A67: Standard | B67: FS-FUFIT-009 | C67: 114003 | D67: 114003 | E67: Nails | F67: Storable Product | G67: ตะปูยิงงานฝีมือ HI-TOP # PINS/25 | H67: HI-TOP Craft Nails # PINS/25 | I67: กล่อง | J67: BOX | L67: =IFERROR(VLOOKUP(K67,'Supplier list'!B:C,2,0),"") | M67: =FALSE() -> 0 | O67: 261
A68: Standard | B68: FS-FUFIT-010 | C68: 114003 | D68: 114003 | E68: Power cord with jack | F68: Storable Product | G68: สายไฟพร้อมแจ๊คเสียบ | H68: Power cord with jack | I68: เส้น | J68: STRIP | L68: =IFERROR(VLOOKUP(K68,'Supplier list'!B:C,2,0),"") | M68: =FALSE() -> 0 | O68: 60
A69: Standard | B69: FS-FUFIT-011 | C69: 114003 | D69: 114003 | E69: Staples | F69: Storable Product | G69: ลูกแม็กขาคู่รุ่น416J ขนาด 4x16 | H69: Staples Double pin model 416J, size 4x16 | I69: กล่อง | J69: BOX | L69: =IFERROR(VLOOKUP(K69,'Supplier list'!B:C,2,0),"") | M69: =FALSE() -> 0 | O69: 93
A70: Standard | B70: FS-FUFIT-012 | C70: 114003 | D70: 114003 | E70: Staples | F70: Storable Product | G70: ลูกแม็กขาคู่รุ่น410J ขนาด 4x10 | H70: Staples Double pin model 416J, size 4x10 | I70: กล่อง | J70: BOX | L70: =IFERROR(VLOOKUP(K70,'Supplier list'!B:C,2,0),"") | M70: =FALSE() -> 0 | O70: 93
A71: Standard | B71: FS-FUFIT-013 | C71: 114003 | D71: 114003 | E71: Power plug | F71: Storable Product | G71: ปลั๊ก3ขา | H71: 3 pin plug | I71: ชิ้น | J71: PC | K71: AP-GDL000 | L71: =IFERROR(VLOOKUP(K71,'Supplier list'!B:C,2,0),"") -> หจก. กรีน ดิสทริบิวชั่น | M71: =FALSE() -> 0 | O71: 28
A72: Standard | B72: FS-FUFIT-014 | C72: 114003 | D72: 114003 | E72: Power plug | F72: Storable Product | G72: ปลั๊ก2ขา | H72: 2 pin plug | I72: ชิ้น | J72: PC | K72: AP-GDL000 | L72: =IFERROR(VLOOKUP(K72,'Supplier list'!B:C,2,0),"") -> หจก. กรีน ดิสทริบิวชั่น | M72: =FALSE() -> 0 | O72: 20
A73: Standard | B73: FS-FUFIT-015 | C73: 114003 | D73: 114003 | E73: Glue | F73: Storable Product | G73: กาวลาเท็กซ์ 32 ออน 12ขวด/ลัง | H73: Latex Glue 32 ounces, 12 bottles/box | I73: ขวด | J73: BOTTLES | K73: AP-KSR001 | L73: =IFERROR(VLOOKUP(K73,'Supplier list'!B:C,2,0),"") | M73: =FALSE() -> 0 | O73: 55
A74: Standard | B74: FS-FUFIT-016 | C74: 114003 | D74: 114003 | E74: Chalk | F74: Storable Product | G74: ชอล์กTOUTH-UPSTLCK NO.101 | H74: Chalk TOUTH-UPSTTLCK NO.101 | I74: แท่ง | J74: STICK | K74: AP-MKW000 | L74: =IFERROR(VLOOKUP(K74,'Supplier list'!B:C,2,0),"") -> บริษัท เอ็มเค วู้ดเทค จำกัด | M74: =FALSE() -> 0 | O74: 80
A75: Standard | B75: FS-FUFIT-017 | C75: 114003 | D75: 114003 | E75: Chalk | F75: Storable Product | G75: ชอล์กTOUTH-UPSTLCK NO.106 | H75: Chalk TOUTH-UPSTTLCK NO.106 | I75: แท่ง | J75: STICK | K75: AP-MKW000 | L75: =IFERROR(VLOOKUP(K75,'Supplier list'!B:C,2,0),"") -> บริษัท เอ็มเค วู้ดเทค จำกัด | M75: =FALSE() -> 0 | O75: 80
...

Sheet Product 652-1300
A1: Standardize | B1: Product Code | C1: Income Account | D1: Expense Account | E1: Product Category | F1: Product Type | G1: Product Name TH | H1: Product Name EN | I1: UOM TH | J1: UOM EN | K1: Code Supplier | L1: Supplier Name | M1: True/False | N1: Selling Price | O1: Cost Price
A2: Standard | B2: RM-FUFIT-190 | C2: 114001 | D2: 114001 | E2: Driver | F2: Storable Product | G2: ไฟ-Haf-833.71.786-หม้อแปลง12V/40W EU PLUG2000mm. | H2: 833.71.786 DRIVER 12V/40W W.EU-PLUG 2000MM | I2: ชิ้น | J2: PC | K2: AP-HAF001 | L2: =IFERROR(VLOOKUP(K2,'Supplier list'!B:C,2,0),"") -> บริษัท เฮเฟเล่ (ประเทศไทย) จำกัด | M2: =TRUE() -> 1 | N2: 2500 | O2: 1421
A3: Standard | B3: RM-FUFIT-191 | C3: 114001 | D3: 114001 | E3: Sink edge | F3: Storable Product | G3: บานซิงค์-0-0-ขอบบานซิงค์ เตาแก๊ส 2.1 เมตร | H3: Zinc door-0-0-Sink edge, gas stove 2.1 meters | I3: เส้น | J3: STRIP | L3: =IFERROR(VLOOKUP(K3,'Supplier list'!B:C,2,0),"") | M3: =FALSE() -> 0 | O3: 988
A4: Standard | B4: RM-FUFIT-192 | C4: 114001 | D4: 114001 | E4: Sink edge | F4: Storable Product | G4: บานซิงค์-0-0-ขอบบานซิงค์ บานเดียว 2.4 เมตร | H4: Sync door-0-0-Edge of sync door, one door 2.4 m. | I4: เส้น | J4: STRIP | L4: =IFERROR(VLOOKUP(K4,'Supplier list'!B:C,2,0),"") | M4: =FALSE() -> 0 | O4: 830
A5: Standard | B5: RM-FUFIT-193 | C5: 114001 | D5: 114001 | E5: Sink edge | F5: Storable Product | G5: บานซิงค์-0-0-ขอบบานซิงค์ ใต้เตาแก๊ส 3 เมตร | H5: Zinc door-0-0-sink edge, under the gas stove 3 meters | I5: เส้น | J5: STRIP | L5: =IFERROR(VLOOKUP(K5,'Supplier list'!B:C,2,0),"") | M5: =FALSE() -> 0 | O5: 1590
A6: Standard | B6: RM-FUFIT-194 | C6: 114001 | D6: 114001 | E6: Aluminum | F6: Storable Product | G6: อลูมิเนียม-จีน-H220-มุมขอบนอก (สีเทาเข้ม) H220 | H6: Aluminum-China-H220-Outer corner (dark grey) H220 | I6: ชิ้น | J6: PC | L6: =IFERROR(VLOOKUP(K6,'Supplier list'!B:C,2,0),"") | M6: =FALSE() -> 0 | O6: 0
A7: Standard | B7: RM-FUFIT-195 | C7: 114001 | D7: 114001 | E7: Pipe clip | F7: Storable Product | G7: ติดตั้ง-0-0-คลิปจับท่อ ก้ามปู 20 PVC ท่อน้ำไทย | H7: Install-0-0-Clip to catch pipe, Claw 20 PVC, Thai water pipes | I7: ชิ้น | J7: PC | L7: =IFERROR(VLOOKUP(K7,'Supplier list'!B:C,2,0),"") | M7: =FALSE() -> 0 | O7: 6
A8: Standard | B8: RM-FUFIT-196 | C8: 114001 | D8: 114001 | E8: Pipe clip | F8: Storable Product | G8: ติดตั้ง-0-0-คลิปจับท่อ ก้ามปู 25 PVC ท่อน้ำไทย | H8: Install-0-0-Clip for pipe clamp, 25 PVC pipe, Thai water pipe | I8: ชิ้น | J8: PC | L8: =IFERROR(VLOOKUP(K8,'Supplier list'!B:C,2,0),"") | M8: =FALSE() -> 0 | O8: 10
A9: Standard | B9: RM-FUFIT-197 | C9: 114001 | D9: 114001 | E9: Pipe clip | F9: Storable Product | G9: ติดตั้ง-0-0-คลิปจับท่อ ก้ามปู 18(1/2)NPI | H9: INSTALL-0-0-Clip, pipe clamp, caliper 18(1/2)NPI | I9: ชิ้น | J9: PC | L9: =IFERROR(VLOOKUP(K9,'Supplier list'!B:C,2,0),"") | M9: =FALSE() -> 0 | O9: 15
A10: Standard | B10: RM-FUFIT-198 | C10: 114001 | D10: 114001 | E10: Joint | F10: Storable Product | G10: ติดตั้ง-0-0-ข้อ90บาง scg บางสีฟ้า35(1.1/4) | H10: Install-0-0-Article 90, some scg, some blue 35(1.1/4) | I10: ชิ้น | J10: PC | K10: AP-KSR001 | L10: =IFERROR(VLOOKUP(K10,'Supplier list'!B:C,2,0),"") -> บริษัท เกรียงศิริพัฒนา (1995) จำกัด | M10: =FALSE() -> 0 | O10: 12
A11: Standard | B11: RM-FUFIT-199 | C11: 114001 | D11: 114001 | E11: Joint | F11: Storable Product | G11: ติดตั้ง-0-0-ข้อต่อตรงscg 35 บาง สีฟ้า(1.1/4) | H11: Install-0-0-Straight Coupling scg 35 Thin Blue (1.1/4) | I11: ชิ้น | J11: PC | K11: AP-KSR001 | L11: =IFERROR(VLOOKUP(K11,'Supplier list'!B:C,2,0),"") -> บริษัท เกรียงศิริพัฒนา (1995) จำกัด | M11: =FALSE() -> 0 | O11: 10
A12: Standard | B12: RM-FUFIT-200 | C12: 114001 | D12: 114001 | E12: Joint | F12: Storable Product | G12: ติดตั้ง-0-0-ข้อ90 บาง ท่อน้ำไทย 3 สีฟ้า | H12: Install-0-0-Article 90 Bang Thai Water Pipe 3 Blue | I12: ชิ้น | J12: PC | L12: =IFERROR(VLOOKUP(K12,'Supplier list'!B:C,2,0),"") | M12: =FALSE() -> 0 | O12: 62
A13: Standard | B13: RM-FUFIT-201 | C13: 114001 | D13: 114001 | E13: Sink edge | F13: Storable Product | G13: บานซิงค์-0-0-ขอบบานซิงค์ บานคู่ 3.2 เมตร | H13: Sync Door-0-0-Edge of Sync Door, Double Door 3.2 m. | I13: เส้น | J13: STRIP | L13: =IFERROR(VLOOKUP(K13,'Supplier list'!B:C,2,0),"") | M13: =FALSE() -> 0 | O13: 990
A14: Standard | B14: RM-FUFIT-202 | C14: 114001 | D14: 114001 | E14: Joint | F14: Storable Product | G14: ติดตั้ง-0-0-สามทางPVC หนา สีฟ้า18(1/2) | H14: Install-0-0-Three Way PVC Thick Blue 18(1/2) | I14: ชิ้น | J14: PC | L14: =IFERROR(VLOOKUP(K14,'Supplier list'!B:C,2,0),"") | M14: =FALSE() -> 0 | O14: 9.5
A15: Standard | B15: RM-FUFIT-204 | C15: 114001 | D15: 114001 | E15: Screw | F15: Storable Product | G15: โครงตู้-0-HC990007-สกรูเกลียวปล่อยหัวแฉก 8*1.1/4 H | H15: Cabinet frame-0-HC990007-Plug head screw 8*1.1/4 H | I15: กล่อง | J15: BOX | K15: AP-KSR001 | L15: =IFERROR(VLOOKUP(K15,'Supplier list'!B:C,2,0),"") -> บริษัท เกรียงศิริพัฒนา (1995) จำกัด | M15: =FALSE() -> 0 | O15: 340
A16: Standard | B16: RM-FUFIT-205 | C16: 114001 | D16: 114001 | E16: Joint | F16: Storable Product | G16: ติดตั้ง-0-0-ข้อต่อตรงลด PVC 40*25(1.1/2*1) | H16: Install-0-0-Straight Coupling PVC 40*25(1.1/2*1) | I16: ชิ้น | J16: PC | L16: =IFERROR(VLOOKUP(K16,'Supplier list'!B:C,2,0),"") | M16: =FALSE() -> 0 | O16: 20
A17: Standard | B17: RM-FUFIT-206 | C17: 114001 | D17: 114001 | E17: Handle | F17: Storable Product | G17: มือจับ-FTT-0-1P004 1 | H17: Handle-FTT-0-1P004 1 | I17: ชิ้น | J17: PC | K17: AP-FTT000 | L17: =IFERROR(VLOOKUP(K17,'Supplier list'!B:C,2,0),"") -> บริษัท ฟิวเจอร์เทค อินเตอร์มาร์เก็ตติ้ง จำกัด | M17: =FALSE() -> 0 | O17: 0
A18: Standard | B18: RM-FUFIT-207 | C18: 114001 | D18: 114001 | E18: Drawer underlay | F18: Storable Product | G18: ติดตั้ง-จีน-0-แผ่นรองใต้ลิ้นชัก ม้วน0.5*15m. | H18: Install-China-0-Pad under the drawer roll 0.5*15m. | I18: เมตร | J18: M | L18: =IFERROR(VLOOKUP(K18,'Supplier list'!B:C,2,0),"") | M18: =FALSE() -> 0 | O18: 99
A19: Standard | B19: RM-FUFIT-208 | C19: 114001 | D19: 114001 | E19: Sticker | F19: Storable Product | G19: ติดตั้ง-จีน-0-สติกเกอร์ปิดเกือกมา สีOaK | H19: Install-China-0-Shoe Cover Sticker, Oak Color | I19: ดวง | J19: DISK | L19: =IFERROR(VLOOKUP(K19,'Supplier list'!B:C,2,0),"") | M19: =FALSE() -> 0 | O19: 30
A20: Standard | B20: RM-FUFIT-209 | C20: 114001 | D20: 114001 | E20: Joint | F20: Storable Product | G20: ติดตั้ง-0-0-ข้อต่อตรง หนา scg 18(1/2) สีฟ้า | H20: Install-0-0-Straight Coupling Thickness scg 18(1/2) Blue | I20: ชิ้น | J20: PC | L20: =IFERROR(VLOOKUP(K20,'Supplier list'!B:C,2,0),"") | M20: =FALSE() -> 0 | O20: 7
A21: Standard | B21: RM-FUFIT-211 | C21: 114001 | D21: 114001 | E21: Cabinet | F21: Storable Product | G21: โครงตู้-จีน-0-ตัวต่อแผ่นรองตู้ครัว9.5 ซม.มุม90 เทา | H21: Cabinet frame-China-0-Kitchen plate connector 9.5 cm. Corner 90 gray | I21: ชิ้น | J21: PC | L21: =IFERROR(VLOOKUP(K21,'Supplier list'!B:C,2,0),"") | M21: =FALSE() -> 0 | O21: 0
A22: Standard | B22: RM-FUFIT-212 | C22: 114001 | D22: 114001 | E22: Cabinet | F22: Storable Product | G22: โครงตู้-0-1C2 9131155-รางลิ้นชักลูกปืน2ตอน | H22: Cabinet Frame-0-1C2 9131155-Bearing drawer slides, 2 sections | I22: ชุด | J22: SET | K22: AP-HAF001 | L22: =IFERROR(VLOOKUP(K22,'Supplier list'!B:C,2,0),"") -> บริษัท เฮเฟเล่ (ประเทศไทย) จำกัด | M22: =FALSE() -> 0 | O22: 660
A23: Standard | B23: RM-FUFIT-213 | C23: 114001 | D23: 114001 | E23: Hinge | F23: Storable Product | G23: โครงตู้-0-1B19076462RC-บานพับถ้วยกระจกMM6204ในขอบ | H23: Cabinet frame-0-1B19076462RC-Glass cup hinge MM6204 in edge | I23: ชุด | J23: SET | K23: AP-HAF001 | L23: =IFERROR(VLOOKUP(K23,'Supplier list'!B:C,2,0),"") -> บริษัท เฮเฟเล่ (ประเทศไทย) จำกัด | M23: =FALSE() -> 0 | O23: 68
A24: Standard | B24: RM-FUFIT-214 | C24: 114001 | D24: 114001 | E24: Cabinet | F24: Storable Product | G24: โครงตู้-Haf-372.91.732-บานเปิดขึ้นFL FFREE FL | H24: 372.91.732 FLF FREE FLAP3.15 F ALU WH. | I24: ชุด | J24: SET | K24: AP-HAF001 | L24: =IFERROR(VLOOKUP(K24,'Supplier list'!B:C,2,0),"") -> บริษัท เฮเฟเล่ (ประเทศไทย) จำกัด | M24: =FALSE() -> 0 | O24: 3673
A25: Standard | B25: RM-FUFIT-215 | C25: 114001 | D25: 114001 | E25: Hinge | F25: Storable Product | G25: บานพับ-Haf-306.00.008-บานพับทับขอบNickleดำเงาsoft | H25: 306.00.008 DAMP.HIN.FULL.EXT.BL.GAL.35MM | I25: ชิ้น | J25: PC | K25: AP-HAF001 | L25: =IFERROR(VLOOKUP(K25,'Supplier list'!B:C,2,0),"") -> บริษัท เฮเฟเล่ (ประเทศไทย) จำกัด | M25: =FALSE() -> 0 | O25: 50
A26: Standard | B26: RM-FUFIT-216 | C26: 114001 | D26: 114001 | E26: Drawer Runners | F26: Storable Product | G26: 432.20.933 รางรับข้างปิดนุ่มนวลรับ นน. 30กก. 400มม | H26: 432.20.933 B-RUNNER S 30F+D GALV.400MM | I26: คู่ | J26: PAIR | K26: AP-HAF001 | L26: =IFERROR(VLOOKUP(K26,'Supplier list'!B:C,2,0),"") -> บริษัท เฮเฟเล่ (ประเทศไทย) จำกัด | M26: =TRUE() -> 1 | N26: 1600 | O26: 655
A27: Standard | B27: RM-FUFIT-217 | C27: 114001 | D27: 114001 | E27: Drawer Runners | F27: Storable Product | G27: ลิ้นชัก-Haf-432.20.935-รางลิ้นชักระบบสองตอน500mm. | H27: Drawer-Haf-432.20.935-Double-section drawer runner, 500mm. | I27: ชิ้น | J27: PC | K27: AP-HAF001 | L27: =IFERROR(VLOOKUP(K27,'Supplier list'!B:C,2,0),"") -> บริษัท เฮเฟเล่ (ประเทศไทย) จำกัด | M27: =TRUE() -> 1 | N27: 1800 | O27: 683
A28: Standard | B28: RM-FUFIT-218 | C28: 114001 | D28: 114001 | E28: Drawer Runners | F28: Storable Product | G28: 432.20.931 รางรับข้างสองตอนรับ นน. 30กก. 300มม. | H28: 432.20.931 B-RUNNER S 30F+D GALV.300MM | I28: คู่ | J28: PAIR | K28: AP-HAF001 | L28: =IFERROR(VLOOKUP(K28,'Supplier list'!B:C,2,0),"") -> บริษัท เฮเฟเล่ (ประเทศไทย) จำกัด | M28: =TRUE() -> 1 | N28: 1400 | O28: 608
A29: Standard | B29: RM-FUFIT-219 | C29: 114001 | D29: 114001 | E29: Drawer Runners | F29: Storable Product | G29: ลิ้นชัก-Haf-552.49.386-ชุดอุปกรณ์ราวด้านข้าง500mm. | H29: 552.49.386 SQUARE RAILLING500MM ST.ANT. | I29: ชุด | J29: SET | K29: AP-HAF001 | L29: =IFERROR(VLOOKUP(K29,'Supplier list'!B:C,2,0),"") -> บริษัท เฮเฟเล่ (ประเทศไทย) จำกัด | M29: =FALSE() -> 0 | O29: 80
A30: Standard | B30: RM-FUFIT-220 | C30: 114001 | D30: 114001 | E30: Drawer Runners | F30: Storable Product | G30: ลิ้นชัก-Haf-552.49.320-ราวขวางกันขวดยาว1200mm. | H30: 552.49.320 CROSS RAILING1200MM ALU.ANT. | I30: ชุด | J30: SET | K30: AP-HAF001 | L30: =IFERROR(VLOOKUP(K30,'Supplier list'!B:C,2,0),"") -> บริษัท เฮเฟเล่ (ประเทศไทย) จำกัด | M30: =FALSE() -> 0 | O30: 68
A31: Standard | B31: RM-FUFIT-221 | C31: 114001 | D31: 114001 | E31: Drawer Runners | F31: Storable Product | G31: ลิ้นชัก-Haf-552.49.325-ตัวยึดราวขวาง | H31: 552.49.325 T-CONNECTOR PLASTIC ANTHRACITE | I31: ชุด | J31: SET | K31: AP-HAF001 | L31: =IFERROR(VLOOKUP(K31,'Supplier list'!B:C,2,0),"") -> บริษัท เฮเฟเล่ (ประเทศไทย) จำกัด | M31: =FALSE() -> 0 | O31: 13
A32: Standard | B32: RM-FUFIT-222 | C32: 114001 | D32: 114001 | E32: Divider | F32: Storable Product | G32: ลิ้นชัก-Haf-552.49.590-อุปกรณ์แบ่งกั้นช่อง | H32: 552.49.590 SHORT PLASTIC DIVIDER ANT. | I32: ชิ้น | J32: PC | K32: AP-HAF001 | L32: =IFERROR(VLOOKUP(K32,'Supplier list'!B:C,2,0),"") -> บริษัท เฮเฟเล่ (ประเทศไทย) จำกัด | M32: =FALSE() -> 0 | O32: 15
A33: Standard | B33: RM-FUFIT-223 | C33: 114001 | D33: 114001 | E33: Cabinet | F33: Storable Product | G33: โครงตู้-0-0-เข้ามุมพลาสติกเคลือบอลูมิเนียมสูง10 ซม | H33: Cabinet frame-0-0-Aluminium-coated plastic corner, height 10 cm. | I33: เส้น | J33: STRIP | K33: AP-HAF001 | L33: =IFERROR(VLOOKUP(K33,'Supplier list'!B:C,2,0),"") -> บริษัท เฮเฟเล่ (ประเทศไทย) จำกัด | M33: =FALSE() -> 0 | O33: 14
A34: Standard | B34: RM-FUFIT-224 | C34: 114001 | D34: 114001 | E34: Cabinet | F34: Storable Product | G34: โครงตู้-0-1AL63300PG3-เฟรมสีพิ้งค์โกลด์แฮร์ลาย3.1M | H34: Cabinet Frame-0-1AL63300PG3-Pink Gold Hair Frame 3.1M Pattern | I34: เส้น | J34: STRIP | K34: AP-FTT000 | L34: =IFERROR(VLOOKUP(K34,'Supplier list'!B:C,2,0),"") -> บริษัท ฟิวเจอร์เทค อินเตอร์มาร์เก็ตติ้ง จำกัด | M34: =FALSE() -> 0 | O34: 0
A35: Standard | B35: RM-FUFIT-225 | C35: 114001 | D35: 114001 | E35: Cabinet | F35: Storable Product | G35: โครงตู้-0-1AL25-PEมุมเฟรม62x62x2.6mm.สีซิงค์ขาว250 | H35: Cabinet frame-0-1AL25-PE frame corner 62x62x2.6mm. White zinc color 250 | I35: ชิ้น | J35: PC | K35: AP-BEST00 | L35: =IFERROR(VLOOKUP(K35,'Supplier list'!B:C,2,0),"") -> Best Solid Surfaces Corp. | M35: =FALSE() -> 0 | O35: 7
A36: Standard | B36: RM-FUFIT-232 | C36: 114001 | D36: 114001 | E36: Cabinet | F36: Storable Product | G36: โครงตู้-TMC-HC991267-ปุ่มกันกระแทก | H36: Cabinet frame-TMC-HC991267-shock button | I36: ชิ้น | J36: PC | K36: AP-FTT000 | L36: =IFERROR(VLOOKUP(K36,'Supplier list'!B:C,2,0),"") -> บริษัท ฟิวเจอร์เทค อินเตอร์มาร์เก็ตติ้ง จำกัด | M36: =FALSE() -> 0 | O36: 1
A37: Standard | B37: RM-FUFIT-233 | C37: 114001 | D37: 114001 | E37: Cabinet | F37: Storable Product | G37: โครงตู้-Haf-564.53.182-Alusplashสีขาว | H37: 564.53.182 A.SPL.GRAPHITE GR ARC WH3100X1500MM | I37: แผ่น | J37: SHEET | K37: AP-HAF001 | L37: =IFERROR(VLOOKUP(K37,'Supplier list'!B:C,2,0),"") -> บริษัท เฮเฟเล่ (ประเทศไทย) จำกัด | M37: =FALSE() -> 0 | O37: 32552
A38: Standard | B38: RM-FUFIT-237 | C38: 114001 | D38: 114001 | E38: Angle bar | F38: Storable Product | G38: ติดตั้ง-FTT-BHD07 115 ZN-เหล็กฉากรูปตัวT | H38: Install-FTT-BHD07 115 ZN-T-angle steel | I38: ชิ้น | J38: PC | K38: AP-FTT000 | L38: =IFERROR(VLOOKUP(K38,'Supplier list'!B:C,2,0),"") -> บริษัท ฟิวเจอร์เทค อินเตอร์มาร์เก็ตติ้ง จำกัด | M38: =FALSE() -> 0 | O38: 60
A39: Standard | B39: RM-FUFIT-238 | C39: 114001 | D39: 114001 | E39: Drawer Runners | F39: Storable Product | G39: ลิ้นชัก-0-1C2 9221508-รางสีซิ้งค์ 40กก/400mm | H39: Drawer-0-1C2 9221508-Sink Rail 40kg/400mm | I39: ชุด | J39: SET | K39: AP-PCS000 | L39: =IFERROR(VLOOKUP(K39,'Supplier list'!B:C,2,0),"") -> บริษัท พรีซิชั่นไลน์ จำกัด | M39: =FALSE() -> 0 | O39: 205
A40: Standard | B40: RM-FUFIT-239 | C40: 114001 | D40: 114001 | E40: Cabinet | F40: Storable Product | G40: โครงตู้-IO-A06 03-คลิปเสียบขาตู้พลาสติกสีดำ-อลู | H40: Cabinet Frame-IO-A06 03-Plastic leg clip, black-aluminum | I40: ชิ้น | J40: PC | K40: AP-IOD000 | L40: =IFERROR(VLOOKUP(K40,'Supplier list'!B:C,2,0),"") -> บริษัท ไอ.โอ.ดีไซน์ แอนด์ โฮม จำกัด | M40: =FALSE() -> 0 | O40: 2.5
...

Sheet 1301-1709
A1: Standardize | B1: Product Code | C1: Income Account | D1: Expense Account | E1: Product Category | F1: Product Type | G1: Product Name TH | H1: Product Name EN | I1: UOM TH | J1: UOM EN | K1: Code Supplier | L1: Supplier Name | M1: True/False | N1: Selling Price | O1: Cost Price
A2: Standard | B2: RM-FUFIT-884 | C2: 114001 | D2: 114001 | E2: Handle | F2: Storable Product | G2: 530011-6106S มือจับ 106ม. สีเงิน | H2: 530011-6106S Handle 106 m. Silver | I2: ชิ้น | J2: PC | K2: AP-PSN000 | L2: =IFERROR(VLOOKUP(K2,'Supplier list'!B:C,2,0),"") | M2: =TRUE() -> 1 | N2: 350 | O2: 180
A3: Standard | B3: RM-FUFIT-885 | C3: 114001 | D3: 114001 | E3: Handle | F3: Storable Product | G3: 530011-6106B มือจับ 106ม. สีดำ | H3: 530011-6106B Handle 106 m. Black | I3: ชิ้น | J3: PC | K3: AP-PSN000 | L3: =IFERROR(VLOOKUP(K3,'Supplier list'!B:C,2,0),"") | M3: =TRUE() -> 1 | N3: 350 | O3: 180
A4: Standard | B4: RM-FUFIT-886 | C4: 114001 | D4: 114001 | E4: Handle | F4: Storable Product | G4: 510026-4128 ปุ่มจับทองเหลือง P128มม. | H4: 510026-4128 Brass Knob P128mm. | I4: ชิ้น | J4: PC | K4: AP-PSN000 | L4: =IFERROR(VLOOKUP(K4,'Supplier list'!B:C,2,0),"") | M4: =TRUE() -> 1 | N4: 1500 | O4: 780
A5: Standard | B5: RM-FUFIT-887 | C5: 114001 | D5: 114001 | E5: Handle | F5: Storable Product | G5: 510026-4000 ปุ่มจับทองเหลือง | H5: 510026-4000 brass knob | I5: ชิ้น | J5: PC | K5: AP-PSN000 | L5: =IFERROR(VLOOKUP(K5,'Supplier list'!B:C,2,0),"") | M5: =TRUE() -> 1 | N5: 450 | O5: 260
A6: Standard | B6: RM-FUFIT-888 | C6: 114001 | D6: 114001 | E6: Handle | F6: Storable Product | G6: 510026-4220 มือจับทองเหลือง P220มม. | H6: 510026-4220 Brass handle P220mm. | I6: ชิ้น | J6: PC | K6: AP-PSN000 | L6: =IFERROR(VLOOKUP(K6,'Supplier list'!B:C,2,0),"") | M6: =TRUE() -> 1 | N6: 1900 | O6: 1220
A7: Standard | B7: RM-FUFIT-889 | C7: 114001 | D7: 114001 | E7: Handle | F7: Storable Product | G7: 520001-6148B มือจับ 148มม. สีดำ | H7: 52001-6148B Handle 148mm. Black | I7: ชิ้น | J7: PC | K7: AP-PSN000 | L7: =IFERROR(VLOOKUP(K7,'Supplier list'!B:C,2,0),"") | M7: =TRUE() -> 1 | N7: 350 | O7: 170
A8: Standard | B8: RM-FUFIT-890 | C8: 114001 | D8: 114001 | E8: Handle | F8: Storable Product | G8: 520001-61000B มือจับ 1000มม. สีดำ | H8: 520001-61000B Handle 1000mm. Black | I8: ชิ้น | J8: PC | K8: AP-PSN000 | L8: =IFERROR(VLOOKUP(K8,'Supplier list'!B:C,2,0),"") | M8: =FALSE() -> 0 | O8: 1300
A9: Standard | B9: RM-FUFIT-891 | C9: 114001 | D9: 114001 | E9: Basket | F9: Storable Product | G9: 546.27.310 ชุดตู้สูงบานดึง Dispensa 150มม. | H9: 546.27.310 Dispensa door pull-out height set, 150mm. | I9: ชุด | J9: SET | K9: AP-HAF001 | L9: =IFERROR(VLOOKUP(K9,'Supplier list'!B:C,2,0),"") -> บริษัท เฮเฟเล่ (ประเทศไทย) จำกัด | M9: =TRUE() -> 1 | N9: 29900 | O9: 17196.5
A10: Standard | B10: RM-FUFIT-892 | C10: 114001 | D10: 114001 | E10: Waste bin | F10: Storable Product | G10: จีน-ถังขยะตะแกรงบานดึง 400มม. | H10: China-Rubber sieve door 400mm. | I10: ชุด | J10: SET | L10: =IFERROR(VLOOKUP(K10,'Supplier list'!B:C,2,0),"") | M10: =TRUE() -> 1 | N10: 4500 | O10: 0
A11: Standard | B11: RM-FUFIT-893 | C11: 114001 | D11: 114001 | E11: Paper box | F11: Storable Product | G11: กล่องKT125/M ใส่ตู้สูง พิมพ์ตามแบบ | H11: Box KT125/M with high cabinet, printed according to the design | I11: ชิ้น | J11: PC | K11: AP-SPS001 | L11: =IFERROR(VLOOKUP(K11,'Supplier list'!B:C,2,0),"") | M11: =FALSE() -> 0 | O11: 124
A12: Standard | B12: RM-FUFIT-894 | C12: 114001 | D12: 114001 | E12: Handle | F12: Storable Product | G12: 1H00700596 มือจับ สีทอง 96มม. | H12: 1H00700596 Handle, gold, 96mm. | I12: ชิ้น | J12: PC | K12: AP-FTT000 | L12: =IFERROR(VLOOKUP(K12,'Supplier list'!B:C,2,0),"") -> บริษัท ฟิวเจอร์เทค อินเตอร์มาร์เก็ตติ้ง จำกัด | M12: =FALSE() -> 0 | O12: 52.5
A13: Standard | B13: RM-FURAW-001 | C13: 114001 | D13: 114001 | E13: Wood | F13: Storable Product | G13: ไม้-MDF E0 CARB-MKW5305 PL:011-Blond Oak-18mm.*4*8 | H13: Wood-MDF E0 CARB-MKW5305 PL:011-Blond Oak-18mm.*4*8 | I13: แผ่น | J13: SHEET | K13: AP-MKW000 | L13: =IFERROR(VLOOKUP(K13,'Supplier list'!B:C,2,0),"") -> บริษัท เอ็มเค วู้ดเทค จำกัด | M13: =FALSE() -> 0 | O13: 220
A14: Standard | B14: RM-FURAW-002 | C14: 114001 | D14: 114001 | E14: Wood | F14: Storable Product | G14: ไม้เปลือย-PB E0-18mm.*4*8 | H14: Bare wood-PB E0-18mm.*4*8 | I14: แผ่น | J14: SHEET | K14: AP-GRP000 | L14: =IFERROR(VLOOKUP(K14,'Supplier list'!B:C,2,0),"") -> บริษัท กรีนรีเวอร์ พาเนล (ประเทศไทย) จำกัด | M14: =FALSE() -> 0 | O14: 336
A15: Standard | B15: RM-FURAW-003 | C15: 114001 | D15: 114001 | E15: Wood | F15: Storable Product | G15: ไม้-MDF E0-MoccaWalnut-MKW5309 PL:06-18mm. | H15: Wood-MDF E0-MoccaWalnut-MKW5309 PL:06-18mm. | I15: แผ่น | J15: SHEET | K15: AP-MKW000 | L15: =IFERROR(VLOOKUP(K15,'Supplier list'!B:C,2,0),"") -> บริษัท เอ็มเค วู้ดเทค จำกัด | M15: =FALSE() -> 0 | O15: 9.1
A16: Standard | B16: RM-FURAW-004 | C16: 114001 | D16: 114001 | E16: Wood | F16: Storable Product | G16: ปิดขอบ-1mm.-28mm.-Hard Oak-MKW5305 | H16: Close the edge -1mm.-28mm.-Hard Oak-MKW5305 | I16: เมตร | J16: M | K16: AP-MKW000 | L16: =IFERROR(VLOOKUP(K16,'Supplier list'!B:C,2,0),"") -> บริษัท เอ็มเค วู้ดเทค จำกัด | M16: =FALSE() -> 0 | O16: 220
A17: Standard | B17: RM-FURAW-005 | C17: 114001 | D17: 114001 | E17: Wood | F17: Storable Product | G17: ปิดขอบ-1mm.-28mm.-Macca Walnut-MKW5309 | H17: Close the edge -1mm.-28mm.-Macca Walnut-MKW5309 | I17: เมตร | J17: M | K17: AP-MKW000 | L17: =IFERROR(VLOOKUP(K17,'Supplier list'!B:C,2,0),"") -> บริษัท เอ็มเค วู้ดเทค จำกัด | M17: =FALSE() -> 0 | O17: 9.1
A18: Standard | B18: RM-FURAW-006 | C18: 114001 | D18: 114001 | E18: Wood | F18: Storable Product | G18: ไม้เปลือย-MDF E2-25mm.*4*8 | H18: Bare-MDF E2-25mm.*4*8 | I18: แผ่น | J18: SHEET | K18: AP-TCH000 | L18: =IFERROR(VLOOKUP(K18,'Supplier list'!B:C,2,0),"") -> บริษัท ไท่ ชาง อินเตอร์เนชั่นแนล คอมเมอร์เชียล เทรด จำกัด | M18: =FALSE() -> 0 | O18: 0
A19: Standard | B19: RM-FURAW-007 | C19: 114001 | D19: 114001 | E19: Wood | F19: Storable Product | G19: ไม้-PB E0-MKW3258 PL:TMC02-Grey-16mm.*4*8 | H19: Wood-PB E0-MKW3258 PL:TMC02-Grey-16mm.*4*8 | I19: แผ่น | J19: SHEET | K19: AP-TCH000 | L19: =IFERROR(VLOOKUP(K19,'Supplier list'!B:C,2,0),"") -> บริษัท ไท่ ชาง อินเตอร์เนชั่นแนล คอมเมอร์เชียล เทรด จำกัด | M19: =FALSE() -> 0 | O19: 915
